<?xml version="1.0"?>
<robot name="px100" xmlns:xacro="http://ros.org/wiki/xacro">

  <xacro:arg name="robot_name" default = "px100"/>
  <xacro:arg name="base_link_frame" default="base_link"/>
  <xacro:arg name="show_ar_tag" default="false"/>
  <xacro:arg name="show_gripper_bar" default="true"/>
  <xacro:arg name="show_gripper_fingers" default="true"/>
  <xacro:arg name="use_world_frame" default="false"/>
  <xacro:arg name="external_urdf_loc" default=""/>
  <xacro:arg name="load_gazebo_configs" default="false"/>

  <xacro:property name="urdf_loc" value="$(arg external_urdf_loc)"/>
  <xacro:property name="pi_offset" value="0.00001"/>

  <xacro:if value="$(arg load_gazebo_configs)">
    <xacro:include filename="$(find interbotix_xsarm_gazebo)/config/interbotix_texture.gazebo"/>
  </xacro:if>

  <material name="interbotix_black">
    <texture filename="package://interbotix_xsarm_descriptions/meshes/interbotix_black.png"/>
  </material>

  <xacro:if value="$(arg use_world_frame)">
    <link name="world"/>
    <joint name="fixed" type="fixed">
      <parent link="world"/>
      <child link="$(arg robot_name)/$(arg base_link_frame)"/>
    </joint>
  </xacro:if>

  <link name="$(arg robot_name)/$(arg base_link_frame)">
    <visual>
      <origin rpy="0 0 ${pi/2}" xyz="0 0 0"/>
      <geometry>
        <mesh filename="package://interbotix_xsarm_descriptions/meshes/px100_meshes/px100_1_base.stl" scale="0.001 0.001 0.001"/>
      </geometry>
      <material name="interbotix_black"/>
    </visual>
    <collision>
      <origin rpy="0 0 ${pi/2}" xyz="0 0 0"/>
      <geometry>
        <mesh filename="package://interbotix_xsarm_descriptions/meshes/px100_meshes/px100_1_base.stl" scale="0.001 0.001 0.001"/>
      </geometry>
    </collision>
    <inertial>
      <origin rpy="0 0 ${pi/2}" xyz="-0.0332053000 0.0008915770 0.0211913000"/>
      <mass value="0.395887" />
      <inertia ixx="0.0010650000" iyy="0.0003332000" izz="0.0012080000" ixy="-0.0000130300" ixz="0.0000018614" iyz="0.0000409200" />
    </inertial>
  </link>

  <joint name="waist" type="revolute">
    <axis xyz="0 0 1"/>
    <limit effort="1" lower="${-pi + pi_offset}" upper="${pi - pi_offset}" velocity="${pi}"/>
    <origin rpy="0 0 0" xyz="0 0 0.05085"/>
    <parent link="$(arg robot_name)/$(arg base_link_frame)"/>
    <child link="$(arg robot_name)/shoulder_link"/>
    <dynamics friction="0.1"/>
  </joint>

  <transmission name="trans_waist">
    <type>transmission_interface/SimpleTransmission</type>
    <joint name="waist">
      <hardwareInterface>hardware_interface/EffortJointInterface</hardwareInterface>
    </joint>
    <actuator name="waist_motor">
      <mechanicalReduction>1</mechanicalReduction>
    </actuator>
  </transmission>

  <link name="$(arg robot_name)/shoulder_link">
    <visual>
      <origin rpy="0 0 ${pi/2}" xyz="0 0 -0.0022"/>
      <geometry>
        <mesh filename="package://interbotix_xsarm_descriptions/meshes/px100_meshes/px100_2_shoulder.stl" scale="0.001 0.001 0.001"/>
      </geometry>
      <material name="interbotix_black"/>
    </visual>
    <collision>
      <origin rpy="0 0 ${pi/2}" xyz="0 0 -0.0022"/>
      <geometry>
        <mesh filename="package://interbotix_xsarm_descriptions/meshes/px100_meshes/px100_2_shoulder.stl" scale="0.001 0.001 0.001"/>
      </geometry>
    </collision>
    <inertial>
      <origin rpy="0 0 ${pi/2}" xyz="0.0000111169 -0.0003605640 0.0284598000"/>
      <mass value="0.072587" />
      <inertia ixx="0.0000231000" iyy="0.0000253500" izz="0.0000144200" ixy="0.0000000003" ixz="0.0000001606" iyz="-0.0000000206" />
    </inertial>
  </link>

  <joint name="shoulder" type="revolute">
    <axis xyz="0 1 0"/>
    <limit effort="2" lower="${radians(-111)}" upper="${radians(107)}" velocity="${pi}"/>
    <origin rpy="0 0 0" xyz="0 0 0.04225"/>
    <parent link="$(arg robot_name)/shoulder_link"/>
    <child link="$(arg robot_name)/upper_arm_link"/>
    <dynamics friction="0.1"/>
  </joint>

  <transmission name="trans_shoulder">
    <type>transmission_interface/SimpleTransmission</type>
    <joint name="shoulder">
      <hardwareInterface>hardware_interface/EffortJointInterface</hardwareInterface>
    </joint>
    <actuator name="shoulder_motor">
      <mechanicalReduction>1</mechanicalReduction>
    </actuator>
  </transmission>

  <link name="$(arg robot_name)/upper_arm_link">
    <visual>
      <origin rpy="0 0 ${pi/2}" xyz="0 0 0"/>
      <geometry>
        <mesh filename="package://interbotix_xsarm_descriptions/meshes/px100_meshes/px100_3_upper_arm.stl" scale="0.001 0.001 0.001"/>
      </geometry>
      <material name="interbotix_black"/>
    </visual>
    <collision>
      <origin rpy="0 0 ${pi/2}" xyz="0 0 0"/>
      <geometry>
        <mesh filename="package://interbotix_xsarm_descriptions/meshes/px100_meshes/px100_3_upper_arm.stl" scale="0.001 0.001 0.001"/>
      </geometry>
    </collision>
    <inertial>
      <origin rpy="0 0 ${pi/2}" xyz="0.0161976963 -0.0002929352 0.0877230000"/>
      <mass value="0.082923" />
      <inertia ixx="0.0000800600" iyy="0.0000745900" izz="0.0000368500" ixy="-0.0000002144" ixz="0.0000002982" iyz="0.0000165700" />
    </inertial>
  </link>

  <joint name="elbow" type="revolute">
    <axis xyz="0 1 0"/>
    <limit effort="2" lower="${radians(-121)}" upper="${radians(92)}" velocity="${pi}"/>
    <origin rpy="0 0 0" xyz="0.035 0 0.1"/>
    <parent link="$(arg robot_name)/upper_arm_link"/>
    <child link="$(arg robot_name)/forearm_link"/>
    <dynamics friction="0.1"/>
  </joint>

  <transmission name="trans_elbow">
    <type>transmission_interface/SimpleTransmission</type>
    <joint name="elbow">
      <hardwareInterface>hardware_interface/EffortJointInterface</hardwareInterface>
    </joint>
    <actuator name="elbow_motor">
      <mechanicalReduction>1</mechanicalReduction>
    </actuator>
  </transmission>

  <link name="$(arg robot_name)/forearm_link">
    <visual>
      <origin rpy="0 0 ${pi/2}" xyz="0 0 0"/>
      <geometry>
        <mesh filename="package://interbotix_xsarm_descriptions/meshes/px100_meshes/px100_4_forearm.stl" scale="0.001 0.001 0.001"/>
      </geometry>
      <material name="interbotix_black"/>
    </visual>
    <collision>
      <origin rpy="0 0 ${pi/2}" xyz="0 0 0"/>
      <geometry>
        <mesh filename="package://interbotix_xsarm_descriptions/meshes/px100_meshes/px100_4_forearm.stl" scale="0.001 0.001 0.001"/>
      </geometry>
    </collision>
    <inertial>
      <origin rpy="0 0 ${pi/2}" xyz="0.0773720000 -0.0003324882 0.0000000000"/>
      <mass value="0.073058" />
      <inertia ixx="0.0000533800" iyy="0.0000165300" izz="0.0000603500" ixy="-0.0000003073" ixz="0.0000000000" iyz="0.0000000000" />
    </inertial>
  </link>



  <xacro:if value="${urdf_loc != ''}">
    <xacro:include filename="${urdf_loc}"/>
  </xacro:if>

</robot>
