<?xml version="1.0"?>
<robot name="neck_vx300" xmlns:xacro="http://ros.org/wiki/xacro">

  <xacro:arg name="robot_name" default = "neck_vx300"/>
  <xacro:arg name="base_link_frame" default="base_link"/>
  <xacro:arg name="show_ar_tag" default="false"/>
  <xacro:arg name="show_gripper_bar" default="false"/>
  <xacro:arg name="show_gripper_fingers" default="false"/>
  <xacro:arg name="use_world_frame" default="false"/>
  <xacro:arg name="external_urdf_loc" default=""/>
  <xacro:arg name="load_gazebo_configs" default="false"/>

  <xacro:property name="urdf_loc" value="$(arg external_urdf_loc)"/>
  <xacro:property name="pi_offset" value="0.00001"/>

  <xacro:if value="$(arg load_gazebo_configs)">
    <xacro:include filename="$(find interbotix_xsarm_gazebo)/config/interbotix_texture.gazebo"/>
  </xacro:if>

  <material name="interbotix_black">
    <texture filename="package://interbotix_xsarm_descriptions/meshes/interbotix_black.png"/>
  </material>

  <xacro:if value="$(arg use_world_frame)">
    <link name="world"/>
    <joint name="fixed" type="fixed">
      <parent link="world"/>
      <child link="$(arg robot_name)/$(arg base_link_frame)"/>
    </joint>
  </xacro:if>

  <link name="$(arg robot_name)/$(arg base_link_frame)">
    <visual>
      <origin rpy="0 0 ${pi/2}" xyz="0 0 0"/>
      <geometry>
        <mesh filename="package://interbotix_xsarm_descriptions/meshes/vx300_meshes/vx300_1_base.stl" scale="0.001 0.001 0.001"/>
      </geometry>
      <material name="interbotix_black"/>
    </visual>
    <collision>
      <origin rpy="0 0 ${pi/2}" xyz="0 0 0"/>
      <geometry>
        <mesh filename="package://interbotix_xsarm_descriptions/meshes/vx300_meshes/vx300_1_base.stl" scale="0.001 0.001 0.001"/>
      </geometry>
    </collision>
    <inertial>
      <origin rpy="0 0 ${pi/2}" xyz="-0.0534774000 -0.0005625750 0.0205961000"/>
      <mass value="0.969034" />
      <inertia ixx="0.0060240000" iyy="0.0017000000" izz="0.0071620000" ixy="0.0000471300" ixz="0.0000038510" iyz="-0.0000841500" />
    </inertial>
  </link>

  <joint name="waist" type="revolute">
    <axis xyz="0 0 1"/>
    <limit effort="10" lower="${-pi + pi_offset}" upper="${pi - pi_offset}" velocity="${pi}"/>
    <origin rpy="0 0 0" xyz="0 0 0.079"/>
    <parent link="$(arg robot_name)/$(arg base_link_frame)"/>
    <child link="$(arg robot_name)/shoulder_link"/>
    <dynamics friction="0.1"/>
  </joint>

  <transmission name="trans_waist">
    <type>transmission_interface/SimpleTransmission</type>
    <joint name="waist">
      <hardwareInterface>hardware_interface/EffortJointInterface</hardwareInterface>
    </joint>
    <actuator name="waist_motor">
      <mechanicalReduction>1</mechanicalReduction>
    </actuator>
  </transmission>

  <link name="$(arg robot_name)/shoulder_link">
    <visual>
      <origin rpy="0 0 ${pi/2}" xyz="0 0 -0.003"/>
      <geometry>
        <mesh filename="package://interbotix_xsarm_descriptions/meshes/vx300_meshes/vx300_2_shoulder.stl" scale="0.001 0.001 0.001"/>
      </geometry>
      <material name="interbotix_black"/>
    </visual>
    <collision>
      <origin rpy="0 0 ${pi/2}" xyz="0 0 -0.003"/>
      <geometry>
        <mesh filename="package://interbotix_xsarm_descriptions/meshes/vx300_meshes/vx300_2_shoulder.stl" scale="0.001 0.001 0.001"/>
      </geometry>
    </collision>
    <inertial>
      <origin rpy="0 0 ${pi/2}" xyz="0.0002592330 -0.0000033552 0.0116129000"/>
      <mass value="0.798614" />
      <inertia ixx="0.0009388000" iyy="0.0011380000" izz="0.0012010000" ixy="-0.0000000010" ixz="-0.0000000191" iyz="0.0000059568" />
    </inertial>
  </link>

  <joint name="shoulder" type="revolute">
    <axis xyz="0 1 0"/>
    <limit effort="20" lower="${radians(-106)}" upper="${radians(72)}" velocity="${pi}"/>
    <origin rpy="0 0 0" xyz="0 0 0.04805"/>
    <parent link="$(arg robot_name)/shoulder_link"/>
    <child link="$(arg robot_name)/upper_arm_link"/>
    <dynamics friction="0.1"/>
  </joint>

  <transmission name="trans_shoulder">
    <type>transmission_interface/SimpleTransmission</type>
    <joint name="shoulder">
      <hardwareInterface>hardware_interface/EffortJointInterface</hardwareInterface>
    </joint>
    <actuator name="shoulder_motor">
      <mechanicalReduction>1</mechanicalReduction>
    </actuator>
  </transmission>

  <link name="$(arg robot_name)/upper_arm_link">
    <visual>
      <origin rpy="0 0 ${pi/2}" xyz="0 0 0"/>
      <geometry>
        <mesh filename="package://interbotix_xsarm_descriptions/meshes/vx300_meshes/vx300_3_upper_arm.stl" scale="0.001 0.001 0.001"/>
      </geometry>
      <material name="interbotix_black"/>
    </visual>
    <collision>
      <origin rpy="0 0 ${pi/2}" xyz="0 0 0"/>
      <geometry>
        <mesh filename="package://interbotix_xsarm_descriptions/meshes/vx300_meshes/vx300_3_upper_arm.stl" scale="0.001 0.001 0.001"/>
      </geometry>
    </collision>
    <inertial>
      <origin rpy="0 0 ${pi/2}" xyz="0.0206949000 0.0000000004 0.2264590000"/>
      <mass value="0.792592" />
      <inertia ixx="0.0089250000" iyy="0.0089370000" izz="0.0009357000" ixy="0.0000000000" ixz="0.0000000000" iyz="0.0012010000" />
    </inertial>
  </link>

  <joint name="elbow" type="revolute">
    <axis xyz="0 1 0"/>
    <limit effort="15" lower="${radians(-101)}" upper="${radians(92)}" velocity="${pi}"/>
    <origin rpy="0 0 0" xyz="0.05955 0 0.3"/>
    <parent link="$(arg robot_name)/upper_arm_link"/>
    <child link="$(arg robot_name)/forearm_link"/>
    <dynamics friction="0.1"/>
  </joint>

  <transmission name="trans_elbow">
    <type>transmission_interface/SimpleTransmission</type>
    <joint name="elbow">
      <hardwareInterface>hardware_interface/EffortJointInterface</hardwareInterface>
    </joint>
    <actuator name="elbow_motor">
      <mechanicalReduction>1</mechanicalReduction>
    </actuator>
  </transmission>

  <link name="$(arg robot_name)/forearm_link">
    <visual>
      <origin rpy="0 0 ${pi/2}" xyz="0 0 0"/>
      <geometry>
        <mesh filename="package://interbotix_xsarm_descriptions/meshes/vx300_meshes/vx300_4_forearm.stl" scale="0.001 0.001 0.001"/>
      </geometry>
      <material name="interbotix_black"/>
    </visual>
    <collision>
      <origin rpy="0 0 ${pi/2}" xyz="0 0 0"/>
      <geometry>
        <mesh filename="package://interbotix_xsarm_descriptions/meshes/vx300_meshes/vx300_4_forearm.stl" scale="0.001 0.001 0.001"/>
      </geometry>
    </collision>
    <inertial>
      <origin rpy="0 0 ${pi/2}" xyz="0.1812650000 -0.0002065037 0.0000000000"/>
      <mass value="0.544659" />
      <inertia ixx="0.0054470000" iyy="0.0002267000" izz="0.0055740000" ixy="-0.0000119800" ixz="0.0000000000" iyz="0.0000000000" />
    </inertial>
  </link>



  <xacro:if value="${urdf_loc != ''}">
    <xacro:include filename="${urdf_loc}"/>
  </xacro:if>

</robot>
